Traceback (most recent call last):
  File "F:\my\P028_knowledge_system\knowqt\qt.py", line 1285, in connect_db
    x = models.Content.objects.filter(id = -100).count()
  File "C:\Users\Administrator\AppData\Local\Programs\Python\Python35\lib\site-packages\django\db\models\query.py", line 364, in count
    return self.query.get_count(using=self.db)
  File "C:\Users\Administrator\AppData\Local\Programs\Python\Python35\lib\site-packages\django\db\models\sql\query.py", line 499, in get_count
    number = obj.get_aggregation(using, ['__count'])['__count']
  File "C:\Users\Administrator\AppData\Local\Programs\Python\Python35\lib\site-packages\django\db\models\sql\query.py", line 480, in get_aggregation
    result = compiler.execute_sql(SINGLE)
  File "C:\Users\Administrator\AppData\Local\Programs\Python\Python35\lib\site-packages\django\db\models\sql\compiler.py", line 899, in execute_sql
    raise original_exception
  File "C:\Users\Administrator\AppData\Local\Programs\Python\Python35\lib\site-packages\django\db\models\sql\compiler.py", line 889, in execute_sql
    cursor.execute(sql, params)
  File "C:\Users\Administrator\AppData\Local\Programs\Python\Python35\lib\site-packages\django\db\backends\utils.py", line 79, in execute
    return super(CursorDebugWrapper, self).execute(sql, params)
  File "C:\Users\Administrator\AppData\Local\Programs\Python\Python35\lib\site-packages\django\db\backends\utils.py", line 64, in execute
    return self.cursor.execute(sql, params)
  File "C:\Users\Administrator\AppData\Local\Programs\Python\Python35\lib\site-packages\django\db\utils.py", line 94, in __exit__
    six.reraise(dj_exc_type, dj_exc_value, traceback)
  File "C:\Users\Administrator\AppData\Local\Programs\Python\Python35\lib\site-packages\django\utils\six.py", line 685, in reraise
    raise value.with_traceback(tb)
  File "C:\Users\Administrator\AppData\Local\Programs\Python\Python35\lib\site-packages\django\db\backends\utils.py", line 64, in execute
    return self.cursor.execute(sql, params)
  File "C:\Users\Administrator\AppData\Local\Programs\Python\Python35\lib\site-packages\django\db\backends\mysql\base.py", line 101, in execute
    return self.cursor.execute(query, args)
  File "C:\Users\Administrator\AppData\Local\Programs\Python\Python35\lib\site-packages\pymysql\cursors.py", line 170, in execute
    result = self._query(query)
  File "C:\Users\Administrator\AppData\Local\Programs\Python\Python35\lib\site-packages\pymysql\cursors.py", line 328, in _query
    conn.query(q)
  File "C:\Users\Administrator\AppData\Local\Programs\Python\Python35\lib\site-packages\pymysql\connections.py", line 516, in query
    self._affected_rows = self._read_query_result(unbuffered=unbuffered)
  File "C:\Users\Administrator\AppData\Local\Programs\Python\Python35\lib\site-packages\pymysql\connections.py", line 727, in _read_query_result
    result.read()
  File "C:\Users\Administrator\AppData\Local\Programs\Python\Python35\lib\site-packages\pymysql\connections.py", line 1066, in read
    first_packet = self.connection._read_packet()
  File "C:\Users\Administrator\AppData\Local\Programs\Python\Python35\lib\site-packages\pymysql\connections.py", line 656, in _read_packet
    packet_header = self._read_bytes(4)
  File "C:\Users\Administrator\AppData\Local\Programs\Python\Python35\lib\site-packages\pymysql\connections.py", line 698, in _read_bytes
    "Lost connection to MySQL server during query (%s)" % (e,))django.db.utils.OperationalError: (2013, 'Lost connection to MySQL server during query ([WinError 10060]????????????????????????????????????????ли?????????????






    111 SELECT @@SQL_AUTO_IS_NULL None
111 SELECT VERSION() None
222 SELECT `data_label`.`id`, `data_label`.`name`, `data_label`.`pid`, `data_label`.`queue`, `data_label`.`grade`, `data_label`.`create_date` FROM `da
ta_label` WHERE `data_label`.`id` = %s LIMIT 1 (3,)
Traceback (most recent call last):
  File "hmysql.py", line 36, in <module>
    x = models.Label.objects.filter(id=3)[0]
  File "C:\Users\Administrator\AppData\Local\Programs\Python\Python35\lib\site-packages\django\db\models\query.py", line 289, in __getitem__
    return list(qs)[0]
  File "C:\Users\Administrator\AppData\Local\Programs\Python\Python35\lib\site-packages\django\db\models\query.py", line 250, in __iter__
    self._fetch_all()
  File "C:\Users\Administrator\AppData\Local\Programs\Python\Python35\lib\site-packages\django\db\models\query.py", line 1118, in _fetch_all
    self._result_cache = list(self._iterable_class(self))
  File "C:\Users\Administrator\AppData\Local\Programs\Python\Python35\lib\site-packages\django\db\models\query.py", line 53, in __iter__
    results = compiler.execute_sql(chunked_fetch=self.chunked_fetch)
  File "C:\Users\Administrator\AppData\Local\Programs\Python\Python35\lib\site-packages\django\db\models\sql\compiler.py", line 901, in execute_sql
    raise original_exception
  File "C:\Users\Administrator\AppData\Local\Programs\Python\Python35\lib\site-packages\django\db\models\sql\compiler.py", line 890, in execute_sql
    raise ValueError('11111111')
ValueError: 11111111



C:\Users\Administrator\AppData\Local\Programs\Python\Python35\lib\site-packages\django\db\models\sql\compiler.py